<?xml version="1.0" ?>
<robot name="mobilerobot">
  <material name="black">
    <color rgba="0.2 0.2 0.2 1"/>
  </material>
  <material name="grey">
    <color rgba="0.75 0.75 0.75 1"/>
  </material>
  <link name="base_link">
    <visual>
      <geometry>
        <mesh filename="package://mobile_robot_description/meshes/raspi_mouse_body.stl"/>
      </geometry>
      <material name="grey"/>
      <origin xyz="-0.041 -0.05 -0.02575" rpy="0 0 0"/>
    </visual>
    <visual name="regulators">
      <geometry>
        <box size="0.005 0.065 0.02"/>
      </geometry>
      <origin xyz="0.04 0 0.036" rpy="0 0 0"/>
      <material name="black"/>
    </visual>
    <visual name="connector">
      <geometry>
        <box size="0.075 0.016 0.026"/>
      </geometry>
      <origin xyz="0 -0.027 0.039" rpy="0 0 0"/>
      <material name="black"/>
    </visual>
    <collision>
      <geometry>
        <box size="0.13 0.1 0.078"/>
      </geometry>
      <origin xyz="0 0 0.013" rpy="0 0 0"/>
    </collision>
    <inertial>
      <origin xyz="0 0 0.013" rpy="0 0 0"/>
      <mass value="0.25"/>
      <inertia ixx="0.0003350833" ixy="0" ixz="0"
        iyy="0.000560417" iyz="0"
        izz="0.000478833"/>
    </inertial>
  </link>

  <link name="caster_support">
    <visual>
      <geometry>
        <mesh filename="package://mobile_robot_description/meshes/mobile_robot_caster.stl"/>
      </geometry>
      <origin xyz="0 0 0" rpy="0 0 0"/>
      <material name="grey"/>
    </visual>
    <collision>
      <geometry>
        <box size="0.04 0.009 0.025"/>
      </geometry>
      <origin xyz="-0.015 0 0" rpy="0 0 0"/>
    </collision>
    <inertial>
      <origin xyz="-0.009725 0 -0.00097398" rpy="0 0 0"/>
      <mass value="0.1"/>
      <inertia ixx="2.677264e-5" ixy="0" ixz="0"
        iyy="7.476213e-5" iyz="0"
        izz="5.655266e-5"/>
    </inertial>
  </link>

  <joint name="caster_support_joint" type="continuous">
    <axis xyz="0 0 1"/>
    <parent link="base_link"/>
    <child link="caster_support"/>
    <origin xyz="-0.065 0 -0.01" rpy="0 0 0"/>
  </joint>

  <link name="caster_wheel">
    <visual>
      <geometry>
        <cylinder length="0.005" radius="0.02"/>
      </geometry>
      <material name="black"/>
    </visual>
    <collision>
      <geometry>
        <cylinder length="0.005" radius="0.02"/>
      </geometry>
    </collision>
    <inertial>
      <mass value="0.1"/>
      <inertia ixx="1.02083e-5" ixy="0" ixz="0"
        iyy="1.02083e-5" iyz="0"
        izz="2e-5"/>
    </inertial>
  </link>

  <joint name="caster_wheel_joint" type="continuous">
    <axis xyz="0 0 1"/>
    <parent link="caster_support"/>
    <child link="caster_wheel"/>
    <origin xyz="-0.02 0 -0.02" rpy="-1.5708 0 0"/>
  </joint>

  <link name="right_wheel">
    <visual>
      <geometry>
        <cylinder length="0.008" radius="0.024"/>
      </geometry>
      <material name="black"/>
    </visual>
    <collision>
      <geometry>
        <cylinder length="0.008" radius="0.024"/>
      </geometry>
    </collision>
    <inertial>
      <mass value="0.1"/>
      <inertia ixx="1.49333e-5" ixy="0" ixz="0"
        iyy="1.49333e-5" iyz="0"
        izz="2.88e-5"/>
    </inertial>
  </link>

  <joint name="right_wheel_joint" type="continuous">
    <axis xyz="0 0 1"/>
    <parent link="base_link"/>
    <child link="right_wheel"/>
    <origin xyz="0 0.054 -0.021" rpy="-1.5708 0 0"/>
  </joint>

  <link name="left_wheel">
    <visual>
      <geometry>
        <cylinder length="0.008" radius="0.024"/>
      </geometry>
      <material name="black"/>
    </visual>
    <collision>
      <geometry>
        <cylinder length="0.008" radius="0.024"/>
      </geometry>
    </collision>
    <inertial>
      <mass value="0.1"/>
      <inertia ixx="1.49333e-5" ixy="0" ixz="0"
        iyy="1.49333e-5" iyz="0"
        izz="2.88e-5"/>
    </inertial>
  </link>

  <joint name="left_wheel_joint" type="continuous">
    <axis xyz="0 0 1"/>
    <parent link="base_link"/>
    <child link="left_wheel"/>
    <origin xyz="0 -0.054 -0.021" rpy="-1.5708 0 0"/>
  </joint>

  <link name="laser">
    <visual>
      <geometry>
        <box size="0.05 0.05 0.05"/>
      </geometry>
      <material name="red">
        <color rgba="0.9 0.1 0.1 1"/>
      </material>
    </visual>
    <collision>
      <geometry>
        <box size="0.05 0.05 0.05"/>
      </geometry>
    </collision>
    <inertial>
      <mass value="0.6"/>
      <inertia ixx="1e-3" ixy="0" ixz="0"
        iyy="1e-3" iyz="0"
        izz="1e-3"/>
    </inertial>
  </link>

  <joint name="laser_joint" type="fixed">
    <parent link="base_link"/>
    <child link="laser"/>
    <origin xyz="0 0 0.051" rpy="0 0 0"/>
  </joint>

  <gazebo>
    <plugin name="differential_drive_controller" filename="libgazebo_ros_diff_drive.so">
      <leftJoint>left_wheel_joint</leftJoint>
      <rightJoint>right_wheel_joint</rightJoint>
      <robotBaseFrame>base_link</robotBaseFrame>
      <wheelSeparation>0.108</wheelSeparation>
      <wheelDiameter>0.024</wheelDiameter>
      <publishWheelJointState>true</publishWheelJointState>
      <legacyMode>true</legacyMode>
    </plugin>

    <plugin name="joint_state_publisher" filename="libgazebo_ros_joint_state_publisher.so">
      <jointName>caster_support_joint, caster_wheel_joint</jointName>
    </plugin>
  </gazebo>

  <gazebo reference="laser">
    <sensor type="gpu_ray" name="laser">
      <pose>0 0 0 0 0 0</pose>
      <visualize>false</visualize>
      <update_rate>40</update_rate>
      <ray>
        <scan>
          <horizontal>
            <samples>720</samples>
            <resolution>1</resolution>
            <min_angle>-1.570796</min_angle>
            <max_angle>1.570796</max_angle>
          </horizontal>
        </scan>
        <range>
          <min>0.1</min>
          <max>30.0</max>
          <resolution>0.01</resolution>
        </range>
      </ray>
      <plugin name="gpu_laser" filename="libgazebo_ros_gpu_laser.so">
        <topicName>/scan</topicName>
        <frameName>laser</frameName>
      </plugin>
    </sensor>
  </gazebo>
</robot>
